Workbook

Sheet 📊 Diagnóstico
A1: DIAGNÓSTICO FINANCEIRO PESSOAL — Calculadora da Virada
A5: Preenche as células a AZUL. As restantes calculam-se automaticamente.
A6: A. INFORMAÇÃO BASE
A7: Nome / Identificação
A8: Mês de referência
A9: Salário / Renda mensal (€/$) | C9: 0
A10: Outras rendas mensais (alugueres, freelance…) | C10: 0
A11: Renda total mensal | C11: =C9+C10 -> 0
A13: B. ACTIVOS (o que possuis)
A14: Descrição | B14: Tipo | C14: Valor actual (€/$) | D14: Rendimento anual (€/$) | E14: Rendimento (%) | F14: Liquidez | G14: Notas
A15: Conta corrente / Carteira | B15: Liquidez | C15: 0 | D15: 0 | E15: =IF(C15=0,0,D15/C15) -> 0 | F15: Imediata
A16: Poupança / Fundo emergência | B16: Liquidez | C16: 0 | D16: 0 | E16: =IF(C16=0,0,D16/C16) -> 0 | F16: Imediata
A17: Investimentos (ETFs/Fundos) | B17: Investimento | C17: 0 | D17: 0 | E17: =IF(C17=0,0,D17/C17) -> 0 | F17: Dias
A18: Imóveis / Casa própria | B18: Real Estate | C18: 0 | D18: 0 | E18: =IF(C18=0,0,D18/C18) -> 0 | F18: Meses
A19: Veículo(s) | B19: Depreciação | C19: 0 | D19: 0 | E19: =IF(C19=0,0,D19/C19) -> 0 | F19: Meses
A20: Negócio próprio | B20: Empreendedor | C20: 0 | D20: 0 | E20: =IF(C20=0,0,D20/C20) -> 0 | F20: Variável
A21: Outros activos | B21: Outro | C21: 0 | D21: 0 | E21: =IF(C21=0,0,D21/C21) -> 0 | F21: Variável
A22: TOTAL ACTIVOS | C22: =SUM(C15:C21) -> 0 | D22: =SUM(D15:D21) -> 0 | E22: =IF(C22=0,0,D22/C22) -> 0
A24: C. PASSIVOS / DÍVIDAS (o que deves)
A25: Credor / Descrição | B25: Tipo | C25: Saldo em dívida (€/$) | D25: Prestação mensal (€/$) | E25: Taxa juro anual (%) | F25: Meses restantes | G25: Prioridade pagamento
A26: Renda / Hipoteca | B26: Habitação | C26: 0 | D26: 0 | E26: 0 | F26: 0
A27: Cartão de crédito | B27: Crédito rotativo | C27: 0 | D27: 0 | E27: 0 | F27: 0
A28: Crédito automóvel | B28: Automóvel | C28: 0 | D28: 0 | E28: 0 | F28: 0
A29: Empréstimo pessoal | B29: Pessoal | C29: 0 | D29: 0 | E29: 0 | F29: 0
A30: Parcelados / BNPL | B30: Parcelado | C30: 0 | D30: 0 | E30: 0 | F30: 0
A31: Outras dívidas | B31: Outro | C31: 0 | D31: 0 | E31: 0 | F31: 0
A32: TOTAL PASSIVOS | C32: =SUM(C26:C31) -> 0 | D32: =SUM(D26:D31) -> 0
A34: D. BALANÇO PATRIMONIAL
A35: Total Activos | C35: =C22 -> 0
A36: Total Passivos | C36: =C32 -> 0
A37: PATRIMÔNIO LÍQUIDO | C37: =C35-C36 -> 0
A38: Rácio Activos/Passivos | C38: =IF(C36=0,"N/A",C35/C36) -> N/A
A40: E. DESPESAS MENSAIS DETALHADAS
A41: Categoria | B41: Descrição | C41: Valor mensal (€/$) | D41: % do salário | E41: Tipo | F41: Essencial? | G41: Notas
A42: 🏠 Habitação | B42: Renda / Hipoteca | C42: 0 | D42: =IF($C$9=0,0,C42/$C$9) -> 0 | E42: Fixo | F42: Sim
A43: 💡 Serviços | B43: Electricidade / Água / Gas | C43: 0 | D43: =IF($C$9=0,0,C43/$C$9) -> 0 | E43: Fixo | F43: Sim
A44: 📱 Comunicações | B44: Internet / Telemóvel | C44: 0 | D44: =IF($C$9=0,0,C44/$C$9) -> 0 | E44: Fixo | F44: Sim
A45: 🛒 Alimentação | B45: Supermercado | C45: 0 | D45: =IF($C$9=0,0,C45/$C$9) -> 0 | E45: Variável | F45: Sim
A46: 🚗 Transporte | B46: Combustível / Transportes | C46: 0 | D46: =IF($C$9=0,0,C46/$C$9) -> 0 | E46: Variável | F46: Sim
A47: 💊 Saúde | B47: Seguros / Consultas | C47: 0 | D47: =IF($C$9=0,0,C47/$C$9) -> 0 | E47: Variável | F47: Sim
...

Sheet 🏥 Score de Saúde
A1: SCORE DE SAÚDE FINANCEIRA
A5: INDICADORES DE SAÚDE FINANCEIRA
A6: Indicador | B6: Fórmula / Fonte | C6: O teu resultado | D6: Pontuação (0-10) | E6: Semáforo | F6: Referência ideal
A7: Taxa de poupança mensal | B7: Renda - Despesas / Renda | C7: =IF('📊 Diagnóstico'!C11=0,0,('📊 Diagnóstico'!C11-'📊 Diagnóstico'!C54)/'📊 Diagnóstico'!C11) -> 0 | D7: =IF(C7>=0.2,10,IF(C7>=0.1,7,IF(C7>=0.05,4,1))) -> 1 | E7: =IF(C7>=0.2,"🟢 Excelente",IF(C7>=0.1,"🟡 Bom",IF(C7>=0.05,"🟠 Atenção","🔴 Crítico"))) -> 🔴 Crítico | F7: >20%
A8: Rácio dívida/renda | B8: Prestações mensais / Renda | C8: =IF('📊 Diagnóstico'!C11=0,0,'📊 Diagnóstico'!D32/'📊 Diagnóstico'!C11) -> 0 | D8: =IF(C8<=0.2,10,IF(C8<=0.35,7,IF(C8<=0.5,4,1))) -> 10 | E8: =IF(C8<=0.2,"🟢 Excelente",IF(C8<=0.35,"🟡 Aceitável",IF(C8<=0.5,"🟠 Atenção","🔴 Crítico"))) -> 🟢 Excelente | F8: <20%
A9: Reserva de emergência (meses) | B9: Activos líquidos / Despesas mensais | C9: =IF('📊 Diagnóstico'!C54=0,0,'📊 Diagnóstico'!C15/'📊 Diagnóstico'!C54) -> 0 | D9: =IF(C9>=6,10,IF(C9>=3,7,IF(C9>=1,4,1))) -> 1 | E9: =IF(C9>=6,"🟢 Excelente",IF(C9>=3,"🟡 Bom",IF(C9>=1,"🟠 Atenção","🔴 Crítico"))) -> 🔴 Crítico | F9: ≥ 6 meses
A10: Índice de liquidez | B10: Activos correntes / Passivos correntes | C10: =IF('📊 Diagnóstico'!C32=0,"N/A",'📊 Diagnóstico'!C22/'📊 Diagnóstico'!C32) -> N/A | D10: =IF(ISNUMBER(C10),IF(C10>=2,10,IF(C10>=1,6,2)),5) -> 5 | E10: =IF(ISNUMBER(C10),IF(C10>=2,"🟢 Excelente",IF(C10>=1,"🟡 OK","🔴 Risco")),"ℹ️ Sem dívidas") -> ℹ️ Sem dívidas | F10: > 2.0
A11: % investido do salário | B11: Investimentos / Renda mensal | C11: =IF('📊 Diagnóstico'!C11=0,0,'📊 Diagnóstico'!C52/'📊 Diagnóstico'!C11) -> 0 | D11: =IF(C11>=0.2,10,IF(C11>=0.1,7,IF(C11>=0.05,4,1))) -> 1 | E11: =IF(C11>=0.2,"🟢 Excelente",IF(C11>=0.1,"🟡 Bom",IF(C11>=0.05,"🟠 Fraco","🔴 Nenhum"))) -> 🔴 Nenhum | F11: ≥ 20%
A12: Peso habitação no orçamento | B12: Custo habitação / Renda | C12: =IF('📊 Diagnóstico'!C11=0,0,'📊 Diagnóstico'!C42/'📊 Diagnóstico'!C11) -> 0 | D12: =IF(C12<=0.3,10,IF(C12<=0.4,6,IF(C12<=0.5,3,1))) -> 10 | E12: =IF(C12<=0.3,"🟢 OK",IF(C12<=0.4,"🟡 Atenção","🔴 Elevado")) -> 🟢 OK | F12: ≤ 30%
A13: SCORE TOTAL (0 – 100) | C13: =SUM(D7:D12)/60*100 -> 46.666667 | E13: =IF(C13>=80,"🏆 Excelente",IF(C13>=60,"🟢 Bom",IF(C13>=40,"🟡 Regular",IF(C13>=20,"🟠 Atenção","🔴 Crítico")))) -> 🟡 Regular
A15: COMO INTERPRETAR O TEU SCORE
A16: 80 – 100 | B16: 🏆 Excelente | C16: Finanças saudáveis. Mantém o rumo e optimiza investimentos.
A17: 60 – 79 | B17: 🟢 Bom | C17: Boa base. Foca em aumentar poupança e reduzir dívidas de alto juro.
A18: 40 – 59 | B18: 🟡 Regular | C18: Algumas áreas precisam atenção. Usa a Calculadora da Virada para criar um plano.
A19: 20 – 39 | B19: 🟠 Atenção | C19: Situação vulnerável. Prioriza reserva de emergência e pagamento de dívidas.
A20: 0 – 19 | B20: 🔴 Crítico | C20: Acção urgente necessária. Reorganiza o orçamento com ajuda do método 50/30/20.

Sheet 🎯 Plano de Acção
A1: PLANO DE ACÇÃO FINANCEIRO — 90 DIAS
A5: 🚨 ACÇÕES IMEDIATAS (Esta semana)
A6: Acção | B6: Descrição adicional | C6: Prazo | D6: Prioridade | E6: Estado | F6: Data conclusão
A7: Preencher toda a planilha de diagnóstico | C7: Até domingo | D7: Alta | E7: ⬜
A8: Criar conta / instalar Calculadora da Virada | C8: Até hoje | D8: Alta | E8: ⬜
A9: Identificar 3 despesas que podes eliminar | C9: Esta semana | D9: Alta | E9: ⬜
A10: Criar fundo de emergência separado | C10: Este mês | D10: Alta | E10: ⬜
A12: 📅 ACÇÕES A 30 DIAS
A13: Acção | B13: Descrição adicional | C13: Prazo | D13: Prioridade | E13: Estado | F13: Data conclusão
A14: Usar a app para registar todas as despesas do mês | C14: Próximos 30 dias | D14: Alta | E14: ⬜
A15: Negociar 1 conta fixa (internet, seguro, etc.) | C15: 2 semanas | D15: Média | E15: ⬜
A16: Abrir conta de investimento (se não tiveres) | C16: Este mês | D16: Alta | E16: ⬜
A17: Definir 2 sonhos na aba Sonhos da app | C17: Esta semana | D17: Média | E17: ⬜
A19: 🚀 ACÇÕES A 90 DIAS
A20: Acção | B20: Descrição adicional | C20: Prazo | D20: Prioridade | E20: Estado | F20: Data conclusão
A21: Chegar a 3 meses de reserva de emergência | C21: 90 dias | D21: Alta | E21: ⬜
A22: Aumentar taxa de poupança para ≥ 10% | C22: 90 dias | D22: Alta | E22: ⬜
A23: Investir consistentemente todos os meses | C23: 90 dias | D23: Alta | E23: ⬜
A24: Rever este diagnóstico e refazer o score | C24: Daqui a 90 dias | D24: Média | E24: ⬜

Sheet 📈 Evolução Mensal
A1: EVOLUÇÃO MENSAL DO PATRIMÔNIO
A5: Métrica | B5: Jan | C5: Fev | D5: Mar | E5: Abr | F5: Mai | G5: Jun | H5: Jul | I5: Ago | J5: Set | K5: Out | L5: Nov | M5: Dez
A6: Renda total | B6: 0 | C6: 0 | D6: 0 | E6: 0 | F6: 0 | G6: 0 | H6: 0 | I6: 0 | J6: 0 | K6: 0 | L6: 0 | M6: 0
A7: Total despesas | B7: 0 | C7: 0 | D7: 0 | E7: 0 | F7: 0 | G7: 0 | H7: 0 | I7: 0 | J7: 0 | K7: 0 | L7: 0 | M7: 0
A8: Poupança do mês | B8: =IF(B6=0,0,B6-B7) -> 0 | C8: =IF(C6=0,0,C6-C7) -> 0 | D8: =IF(D6=0,0,D6-D7) -> 0 | E8: =IF(E6=0,0,E6-E7) -> 0 | F8: =IF(F6=0,0,F6-F7) -> 0 | G8: =IF(G6=0,0,G6-G7) -> 0 | H8: =IF(H6=0,0,H6-H7) -> 0 | I8: =IF(I6=0,0,I6-I7) -> 0 | ... M8: =IF(M6=0,0,M6-M7) -> 0
A9: Taxa de poupança | B9: =IF(B6=0,0,B8/B6) -> 0 | C9: =IF(C6=0,0,C8/C6) -> 0 | D9: =IF(D6=0,0,D8/D6) -> 0 | E9: =IF(E6=0,0,E8/E6) -> 0 | F9: =IF(F6=0,0,F8/F6) -> 0 | G9: =IF(G6=0,0,G8/G6) -> 0 | H9: =IF(H6=0,0,H8/H6) -> 0 | I9: =IF(I6=0,0,I8/I6) -> 0 | ... M9: =IF(M6=0,0,M8/M6) -> 0
A10: Activos totais | B10: 0 | C10: 0 | D10: 0 | E10: 0 | F10: 0 | G10: 0 | H10: 0 | I10: 0 | J10: 0 | K10: 0 | L10: 0 | M10: 0
A11: Passivos totais | B11: 0 | C11: 0 | D11: 0 | E11: 0 | F11: 0 | G11: 0 | H11: 0 | I11: 0 | J11: 0 | K11: 0 | L11: 0 | M11: 0
A12: Patrimônio líquido | B12: =IF(B10=0,0,B10-B11) -> 0 | C12: =IF(C10=0,0,C10-C11) -> 0 | D12: =IF(D10=0,0,D10-D11) -> 0 | E12: =IF(E10=0,0,E10-E11) -> 0 | F12: =IF(F10=0,0,F10-F11) -> 0 | G12: =IF(G10=0,0,G10-G11) -> 0 | H12: =IF(H10=0,0,H10-H11) -> 0 | I12: =IF(I10=0,0,I10-I11) -> 0 | ... M12: =IF(M10=0,0,M10-M11) -> 0
A13: Score de saúde | B13: 0 | C13: 0 | D13: 0 | E13: 0 | F13: 0 | G13: 0 | H13: 0 | I13: 0 | J13: 0 | K13: 0 | L13: 0 | M13: 0
A15: 💡 Dica: Copia os valores do Histórico da Calculadora da Virada para esta tabela mensalmente para acompanhar a tua evolução patrimonial ao longo do ano.
